Workbook

Sheet алые 25
A1: Наименование | B1: Состав | C1: объем | D1: ст. литра | E1: сс | F1: сс позиции | G1: Цена | H1: НАЦЕНКА
A2: Patience | B2: Джин - 40 | C2: 0.04 | D2: =#REF! -> #REF! | E2: =D2*C2 -> #REF! | F2: =SUM(E2:E8) -> #REF! | G2: 700 | H2: =(G2-F2)/F2*100 -> #REF!
B3: Персиковый ликер 20 | C3: 0.02 | D3: =#REF! -> #REF! | E3: =D3*C3 -> #REF!
B4: Сок яблоко 60 | C4: 0.06 | D4: =#REF! -> #REF! | E4: =D4*C4 -> #REF!
B5: Сироп юзу 10 | C5: 0.01 | D5: 480 | E5: =D5*C5 -> 4.8
B6: Сироп ваниль 20 | C6: 0.02 | D6: =#REF! -> #REF! | E6: =D6*C6 -> #REF!
B7: белок | C7: 0.02 | D7: =#REF! -> #REF! | E7: =D7*C7 -> #REF!
B8: Лимонный 30 | C8: 0.06 | D8: =#REF! -> #REF! | E8: =D8*C8 -> #REF!
A9: Scarlet Sails | B9: Водка 40 | C9: 0.04 | D9: =#REF! -> #REF! | E9: =D9*C9 -> #REF! | F9: =SUM(E9:E14) -> #REF! | G9: 700 | H9: =(G9-F9)/F9*100 -> #REF!
B10: Малина ликер 20 | C10: 0.02 | D10: =#REF! -> #REF! | E10: =D10*C10 -> #REF!
B11: Малина пюре 20 | C11: 0.02 | D11: =#REF! -> #REF! | E11: =D11*C11 -> #REF!
B12: Лимон 20 | C12: 0.04 | D12: =#REF! -> #REF! | E12: =D12*C12 -> #REF!
B13: Ананас сок 80 | C13: 0.08 | D13: =#REF! -> #REF! | E13: =D13*C13 -> #REF!
E14: =D14*C14 -> 0
A15: Future | B15: Ром 60 | C15: 0.06 | D15: =#REF! -> #REF! | E15: =D15*C15 -> #REF! | F15: =SUM(E15:E20) -> #REF! | G15: 1100 | H15: =(G15-F15)/F15*100 -> #REF!
B16: Кокос ликер 40 | C16: 0.04 | D16: =#REF! -> #REF! | E16: =D16*C16 -> #REF!
B17: Лимон 30 | C17: 0.06 | D17: =#REF! -> #REF! | E17: =D17*C17 -> #REF!
B18: Ваниль 30 | C18: 0.03 | D18: =#REF! -> #REF! | E18: =D18*C18 -> #REF!
E19: =D19*C19 -> 0
E20: =D20*C20 -> 0
A21: Summer snow | B21: Водка 60 | C21: 0.06 | D21: =#REF! -> #REF! | E21: =D21*C21 -> #REF! | F21: =SUM(E21:E26) -> #REF! | G21: 1100 | H21: =(G21-F21)/F21*100 -> #REF!
B22: Кофейный 60 | C22: 0.06 | D22: =#REF! -> #REF! | E22: =D22*C22 -> #REF!
B23: Сливки 40 | C23: 0.04 | D23: =#REF! -> #REF! | E23: =D23*C23 -> #REF!
E24: =D24*C24 -> 0
E25: =D25*C25 -> 0
E26: =D26*C26 -> 0
E27: =D27*C27 -> 0 | F27: =SUM(E27:E32) -> 0 | H27: =(G27-F27)/F27*100 -> #DIV/0!
E28: =D28*C28 -> 0
E29: =D29*C29 -> 0
E30: =D30*C30 -> 0
E31: =D31*C31 -> 0
E32: =D32*C32 -> 0
E33: =D33*C33 -> 0 | F33: =SUM(E33:E38) -> 0 | H33: =(G33-F33)/F33*100 -> #DIV/0!
E34: =D34*C34 -> 0
E35: =D35*C35 -> 0
E36: =D36*C36 -> 0
E37: =D37*C37 -> 0
E38: =D38*C38 -> 0
E39: =D39*C39 -> 0 | F39: =SUM(E39:E44) -> 0 | H39: =(G39-F39)/F39*100 -> #DIV/0!
E40: =D40*C40 -> 0
...

Sheet 14.02
A1: Наименование | B1: Состав | C1: объем | D1: ст. литра | E1: сс | F1: сс позиции | G1: Цена | H1: НАЦЕНКА
A2: Love is, 300ml | B2: Rum Diablo Negro Caribbean 0,04 | C2: 40 | D2: =#REF! -> #REF! | E2: =D2/1000*C2 -> #REF! | F2: =SUM(E2:E7) -> #REF! | G2: 700 | H2: =(G2-F2)/F2*100 -> #REF!
B3: Niva Distillery Liquor coconut 0,02 | C3: 20 | D3: =#REF! -> #REF! | E3: =D3/1000*C3 -> #REF!
B4: Cordial Clavis tonka beans 0,02 | C4: 20 | D4: =#REF! -> #REF! | E4: =D4/1000*C4 -> #REF!
B5: Cream 0,02 | C5: 20 | D5: =#REF! -> #REF! | E5: =D5/1000*C5 -> #REF!
B6: Syrup bubble gum 0,025 | C6: 25 | D6: =#REF! -> #REF! | E6: =D6/1000*C6 -> #REF!
B7: Candy | E7: 5
A8: Kiss me, 300ml | B8: Rum Diablo Negro Caribbean 0,04 | C8: 40 | D8: =#REF! -> #REF! | E8: =D8/1000*C8 -> #REF!
B9: Niva Distillery Liquor raspberry 0,02 | C9: 20 | D9: =#REF! -> #REF! | E9: =D9/1000*C9 -> #REF! | F9: =SUM(E8:E15) -> #REF! | G9: 700 | H9: =(G9-F9)/F9*100 -> #REF!
B10: Syrup cherry 0,01 | C10: 10 | D10: =#REF! -> #REF! | E10: =D10/1000*C10 -> #REF!
B11: Syrup almond 0,015 | C11: 15 | D11: =#REF! -> #REF! | E11: =D11/1000*C11 -> #REF!
B12: Cream 0,03 | C12: 30 | D12: =#REF! -> #REF! | E12: =D12/1000*C12 -> #REF!
B13: Pineapple juice 0,05 | C13: 50 | D13: =#REF! -> #REF! | E13: =D13/1000*C13 -> #REF!
B14: Apple juice 0,05 | C14: 50 | D14: =#REF! -> #REF! | E14: =D14/1000*C14 -> #REF!
B15: Candy | E15: 5
A16: Romeo and Juliet, 300ml | B16: Gin Royal Raven Dry 0,02 | C16: 20 | D16: =#REF! -> #REF! | E16: =D16/1000*C16 -> #REF! | F16: =SUM(E16:E21) -> #REF! | G16: 700 | H16: =(G16-F16)/F16*100 -> #REF!
B17: Niva Distillery Liquor elderflower 0,02 | C17: 20 | D17: =#REF! -> #REF! | E17: =D17/1000*C17 -> #REF!
B18: Cordial Clavis banana 0,02 | C18: 20 | D18: =#REF! -> #REF! | E18: =D18/1000*C18 -> #REF!
B19: Lemon fresh 0,01 | C19: 20 | D19: 250 | E19: =D19/1000*C19 -> 5
B20: Syrup cinnamon 0,02 | C20: 20 | D20: =#REF! -> #REF! | E20: =D20/1000*C20 -> #REF!
B21: Candy | D21: 5 | E21: 5
A23: Set shots 4х40ml
A24: Первое свидание | B24: Rum Diablo Negro Caribbean 0,04 | C24: 40 | D24: =#REF! -> #REF! | E24: =D24/1000*C24 -> #REF! | F24: =SUM(E24:E26) -> #REF! | G24: 1000 | H24: =(G24-F24)/F24*100 -> #REF!
B25: Lemon fresh 0,04 | C25: 80 | D25: 250 | E25: =D25/1000*C25 -> 20
B26: Niva Distillery Liquor raspberry 0,04 | C26: 40 | D26: =#REF! -> #REF! | E26: =D26/1000*C26 -> #REF!
B27: Syrup popcorn 0,04 | C27: 40 | D27: =#REF! -> #REF! | E27: =D27/1000*C27 -> #REF!

Sheet 23.02
A1: Наименование | B1: Состав | C1: объем | D1: ст. литра | E1: сс | F1: сс позиции | G1: Цена | H1: НАЦЕНКА
A2: Сын маминой подруги, 300ml | B2: Niva Distillery Sambuca 0,02 | C2: 20 | D2: =#REF! -> #REF! | E2: =D2/1000*C2 -> #REF! | F2: =SUM(E2:E7) -> #REF! | G2: 700 | H2: =(G2-F2)/F2*100 -> #REF!
B3: Absinthe Oasis 0,02 | C3: 20 | D3: =#REF! -> #REF! | E3: =D3/1000*C3 -> #REF!
B4: Syrup coconut 0,02 | C4: 20 | D4: =#REF! -> #REF! | E4: =D4/1000*C4 -> #REF!
B5: Lemon fresh 0,015 | C5: 30 | D5: 250 | E5: =D5/1000*C5 -> 7.5
B6: Red Bull tropical 0,5шт | C6: 0.5 | D6: =#REF! -> #REF! | E6: =D6*C6 -> #REF!
B7: Orange 0,015 | C7: 15 | D7: 250 | E7: =D7/1000*C7 -> 3.75
A8: Джентельмен, 300ml | B8: Whiskey Your Choice 0,04 | C8: 40 | D8: =#REF! -> #REF! | E8: =D8/1000*C8 -> #REF! | F8: =SUM(E8:E14) -> #REF! | G8: 700 | H8: =(G8-F8)/F8*100 -> #REF!
B9: Niva Distillery Liquor elderflower 0,02 | C9: 20 | D9: =#REF! -> #REF! | E9: =D9/1000*C9 -> #REF!
B10: Syrup cinnamon 0,015 | C10: 15 | D10: =#REF! -> #REF! | E10: =D10/1000*C10 -> #REF!
B11: Lemon fresh 0,02 | C11: 40 | D11: 250 | E11: =D11/1000*C11 -> 10
B12: Apple juice 0,1 | C12: 100 | D12: =#REF! -> #REF! | E12: =D12/1000*C12 -> #REF!
B13: Lemon 0,015 | C13: 15 | D13: 250 | E13: =D13/1000*C13 -> 3.75
E14: =D14/1000*C14 -> 0
A15: Малиновый пиджак, 300ml | B15: Vodka Хаски 0,04 | C15: 40 | D15: =#REF! -> #REF! | E15: =D15/1000*C15 -> #REF! | F15: =SUM(E15:E20) -> #REF! | G15: 700 | H15: =(G15-F15)/F15*100 -> #REF!
B16: Niva Distillery Liquor raspberry 0,02 | C16: 20 | D16: =#REF! -> #REF! | E16: =D16/1000*C16 -> #REF!
B17: Syrup bubble gum 0,01 | C17: 10 | D17: =#REF! -> #REF! | E17: =D17/1000*C17 -> #REF!
B18: Lemon fresh 0,02 | C18: 40 | D18: 250 | E18: =D18/1000*C18 -> 10
B19: Sprite 0,1 | C19: 100 | D19: =#REF! -> #REF! | E19: =D19/1000*C19 -> #REF!
B20: Lemon 0,015 | C20: 15 | D20: 250 | E20: =D20/1000*C20 -> 3.75
A21: Крепкий орешек, 300ml | B21: Tequila el charro 0,02 | C21: 20 | D21: =#REF! -> #REF! | E21: =D21/1000*C21 -> #REF! | F21: =SUM(E21:E26) -> #REF! | G21: 700 | H21: =(G21-F21)/F21*100 -> #REF!
B22: Niva Distillery Liquor lychee 0,02 | C22: 20 | D22: =#REF! -> #REF! | E22: =D22/1000*C22 -> #REF!
B23: Syrup yuzu 0,01 | C23: 10 | D23: =#REF! -> #REF! | E23: =D23/1000*C23 -> #REF!
B24: Lemon fresh 0,015 | C24: 30 | D24: 250 | E24: =D24/1000*C24 -> 7.5
B25: Grapefruit juice 0,06 | C25: 60 | D25: =#REF! -> #REF! | E25: =D25/1000*C25 -> #REF!
B26: Like 0,01 | C26: 10 | D26: 250 | E26: =D26/1000*C26 -> 2.5
A28: Set shots 4х40ml
A29: По-братски | B29: Vodka Хаски 0,04 | C29: 40 | D29: =#REF! -> #REF! | E29: =D29/1000*C29 -> #REF! | F29: =SUM(E29:E32) -> #REF! | G29: 1000 | H29: =(G29-F29)/F29*100 -> #REF!
B30: Niva Distillery Liquor cream 0,04 | C30: 40 | D30: =#REF! -> #REF! | E30: =D30/1000*C30 -> #REF!
B31: Syrup blackberry 0,04 | C31: 40 | D31: =#REF! -> #REF! | E31: =D31/1000*C31 -> #REF!
B32: Cream 0,04 | C32: 40 | D32: =#REF! -> #REF! | E32: =D32/1000*C32 -> #REF!

Sheet 8.03
A1: Наименование | B1: Состав | C1: объем | D1: ст. литра | E1: сс | F1: сс позиции | G1: Цена | H1: НАЦЕНКА
A2: Звонок бывшему, 150ml | B2: Niva Distillery Sambuca 0,03 | C2: 30 | D2: =#REF! -> #REF! | E2: =D2/1000*C2 -> #REF! | F2: =SUM(E2:E7) -> #REF! | G2: 750 | H2: =(G2-F2)/F2*100 -> #REF!
B3: Niva Distillery Liquor coffee 0,04 | C3: 40 | D3: =#REF! -> #REF! | E3: =D3/1000*C3 -> #REF!
B4: Syrup cinnamon 0,015 | C4: 15 | D4: 420 | E4: =D4/1000*C4 -> 6.3
B5: Cream 0,04 | C5: 40 | D5: =#REF! -> #REF! | E5: =D5/1000*C5 -> #REF!
B6: Candy | D6: 10 | E6: 10
E7: =D7/1000*C7 -> 0
A8: Тропикана женщина, 300ml | B8: Rum Diablo Negro Caribbean 0,04 | C8: 40 | D8: =#REF! -> #REF! | E8: =D8/1000*C8 -> #REF! | F8: =SUM(E8:E14) -> #REF! | G8: 750 | H8: =(G8-F8)/F8*100 -> #REF!
B9: Niva Distillery Aperitivo 0,04 | C9: 40 | D9: =#REF! -> #REF! | E9: =D9/1000*C9 -> #REF!
B10: Lemon fresh 0,02 | C10: 40 | D10: 250 | E10: =D10/1000*C10 -> 10
B11: Pineapple juice 0,05 | C11: 50 | D11: =#REF! -> #REF! | E11: =D11/1000*C11 -> #REF!
B12: Seven up 0,05 | C12: 50 | D12: =#REF! -> #REF! | E12: =D12/1000*C12 -> #REF!
B13: Flowers | D13: 10 | E13: 10
E14: =D14/1000*C14 -> 0
A15: Женщина в красном, 150ml | B15: Rum Diablo Negro Caribbean 0,04 | C15: 40 | D15: =#REF! -> #REF! | E15: =D15/1000*C15 -> #REF! | F15: =SUM(E15:E20) -> #REF! | G15: 750 | H15: =(G15-F15)/F15*100 -> #REF!
B16: Niva Distillery Liquor raspberry 0,02 | C16: 20 | D16: =#REF! -> #REF! | E16: =D16/1000*C16 -> #REF!
B17: Niva Distillery Liquor triple sec 0,02 | C17: 20 | D17: =#REF! -> #REF! | E17: =D17/1000*C17 -> #REF!
B18: Lemon fresh 0,02 | C18: 40 | D18: 250 | E18: =D18/1000*C18 -> 10
B19: Syrup cherry 0,02 | C19: 20 | D19: =#REF! -> #REF! | E19: =D19/1000*C19 -> #REF!
B20: Candy | D20: 10 | E20: 10
A22: Set shots 4х40ml
A23: Завтрак у Тиффани | B23: Rum Diablo Negro Caribbean 0,04 | C23: 40 | D23: =#REF! -> #REF! | E23: =D23/1000*C23 -> #REF! | F23: =SUM(E23:E28) -> #REF! | G23: 1100 | H23: =(G23-F23)/F23*100 -> #REF!
B24: Niva Distillery Liquor melon 0,03 | C24: 30 | D24: =#REF! -> #REF! | E24: =D24/1000*C24 -> #REF!
B25: Niva Distillery Liquor blue curaçao 0,03 | C25: 30 | D25: =#REF! -> #REF! | E25: =D25/1000*C25 -> #REF!
B26: Cream 0,04 | C26: 40 | D26: =#REF! -> #REF! | E26: =D26/1000*C26 -> #REF!
B27: Syrup coconut 0,02 | C27: 20 | D27: =#REF! -> #REF! | E27: =D27/1000*C27 -> #REF!
E28: =D28/1000*C28 -> 0

Sheet 12.04
A1: Наименование | B1: Состав | C1: объем | D1: ст. литра | E1: сс | F1: сс позиции | G1: Цена | H1: НАЦЕНКА
A2: Harlequin, 300ml | B2: Gin Royal Raven Dry 0,04 | C2: 40 | D2: =#REF! -> #REF! | E2: =D2/1000*C2 -> #REF! | F2: =SUM(E2:E7) -> #REF! | G2: 700 | H2: =(G2-F2)/F2*100 -> #REF!
B3: Niva Distillery Liquor lychee 0,02 | C3: 20 | D3: =#REF! -> #REF! | E3: =D3/1000*C3 -> #REF!
B4: Syrup cherry 0,02 | C4: 20 | D4: 420 | E4: =D4/1000*C4 -> 8.4
B5: Grapefruit juice 0,1 | C5: 100 | D5: 170 | E5: =D5/1000*C5 -> 17
B6: Lemon fresh 0,02 | C6: 40 | D6: 260 | E6: =D6/1000*C6 -> 10.4
B7: Candy | E7: 10
A8: Hocus Pocus, 300ml | B8: Rum Diablo Negro Caribbean 0,04 | C8: 40 | D8: =#REF! -> #REF! | E8: =D8/1000*C8 -> #REF! | F8: =SUM(E8:E14) -> #REF! | G8: 700 | H8: =(G8-F8)/F8*100 -> #REF!
B9: Niva Distillery Liquor melon 0,02 | C9: 20 | D9: =#REF! -> #REF! | E9: =D9/1000*C9 -> #REF!
B10: Syrup honey 0,02 | C10: 20 | D10: 420 | E10: =D10/1000*C10 -> 8.4
B11: Apple juice 0,1 | C11: 100 | D11: 170 | E11: =D11/1000*C11 -> 17
B12: Lemon fresh 0,02 | C12: 40 | D12: 260 | E12: =D12/1000*C12 -> 10.4
B13: Candy | E13: 10
E14: =D14/1000*C14 -> 0
A15: Rabbit in a hat, 300ml | B15: Gin Royal Raven Dry 0,04 | C15: 40 | D15: =#REF! -> #REF! | E15: =D15/1000*C15 -> #REF! | F15: =SUM(E15:E20) -> #REF! | G15: 700 | H15: =(G15-F15)/F15*100 -> #REF!
B16: Niva Distillery Liquor coconut 0,02 | C16: 20 | D16: =#REF! -> #REF! | E16: =D16/1000*C16 -> #REF!
B17: Syrup raspberry 0,02 | C17: 20 | D17: 420 | E17: =D17/1000*C17 -> 8.4
B18: Pineapple juice 0,1 | C18: 100 | D18: 170 | E18: =D18/1000*C18 -> 17
B19: Lemon fresh 0,02 | C19: 40 | D19: 260 | E19: =D19/1000*C19 -> 10.4
B20: Candy | E20: 10
A22: Set shots 4х40ml
A23: Freak show | B23: Rum Diablo Negro Caribbean 0,04 | C23: 40 | D23: =#REF! -> #REF! | E23: =D23/1000*C23 -> #REF! | F23: =SUM(E23:E28) -> #REF! | G23: 1000 | H23: =(G23-F23)/F23*100 -> #REF!
B24: Niva Distillery Liquor melon 0,03 | C24: 30 | D24: =#REF! -> #REF! | E24: =D24/1000*C24 -> #REF!
B25: Niva Distillery Liquor blue curaçao 0,03 | C25: 30 | D25: =#REF! -> #REF! | E25: =D25/1000*C25 -> #REF!
B26: Cream 0,04 | C26: 40 | D26: =#REF! -> #REF! | E26: =D26/1000*C26 -> #REF!
B27: Syrup coconut 0,02 | C27: 20 | D27: =#REF! -> #REF! | E27: =D27/1000*C27 -> #REF!
E28: =D28/1000*C28 -> 0

Sheet большие к-ли
A1: Наименование | B1: Состав | C1: объем | D1: ст. литра | E1: сс | F1: сс позиции | G1: Цена | H1: НАЦЕНКА
A2: Биг Пасадена | B2: Джин хаус 150 | C2: 0.15 | D2: =#REF! -> #REF! | E2: =D2*C2 -> #REF! | F2: =SUM(E2:E7) -> #REF! | G2: 2000 | H2: =(G2-F2)/F2*100 -> #REF!
B3: Ликер дыня 100 | C3: 0.1 | D3: =#REF! -> #REF! | E3: =D3*C3 -> #REF!
B4: Фреш 100 | C4: 0.2 | D4: 250 | E4: =D4*C4 -> 50
B5: Сок ананас 300 | C5: 0.3 | D5: =#REF! -> #REF! | E5: =D5*C5 -> #REF!
B6: Сироп банан 100 | C6: 0.1 | D6: 420 | E6: =D6*C6 -> 42
E7: =D7*C7 -> 0
A8: Биг текила санрайз | B8: Текила хаус 200 | C8: 0.2 | D8: =#REF! -> #REF! | E8: =D8*C8 -> #REF! | F8: =SUM(E8:E14) -> #REF! | G8: 2000 | H8: =(G8-F8)/F8*100 -> #REF!
B9: Гренадин сироп 100 | C9: 0.1 | D9: 420 | E9: =D9*C9 -> 42
B10: Сок апельсин 400 | C10: 0.4 | D10: =#REF! -> #REF! | E10: =D10*C10 -> #REF!
E11: =D11*C11 -> 0
E12: =D12*C12 -> 0
E13: =D13*C13 -> 0
E14: =D14*C14 -> 0
A15: Биг Лонг Айленд | B15: Хаски 80 | C15: 0.08 | D15: =#REF! -> #REF! | E15: =D15*C15 -> #REF! | F15: =SUM(E15:E21) -> #REF! | G15: 2000 | H15: =(G15-F15)/F15*100 -> #REF!
B16: Текила 80 | C16: 0.08 | D16: =#REF! -> #REF! | E16: =D16*C16 -> #REF!
B17: Джин 80 | C17: 0.08 | D17: =#REF! -> #REF! | E17: =D17*C17 -> #REF!
B18: Ром 80 | C18: 0.08 | D18: =#REF! -> #REF! | E18: =D18*C18 -> #REF!
B19: Трипл сек ликер 80 | C19: 0.08 | D19: =#REF! -> #REF! | E19: =D19*C19 -> #REF!
B20: Лимон 80 | C20: 0.08 | D20: 250 | E20: =D20*C20 -> 20
B21: Кола 300 | C21: 0.3 | D21: =#REF! -> #REF! | E21: =D21*C21 -> #REF!
A22: Биг Блю Лайн | B22: Джин 150 | C22: 0.15 | D22: =#REF! -> #REF! | E22: =D22*C22 -> #REF! | F22: =SUM(E22:E27) -> #REF! | G22: 2000 | H22: =(G22-F22)/F22*100 -> #REF!
B23: Ликер блю Кюрасао 100 | C23: 0.1 | D23: =#REF! -> #REF! | E23: =D23*C23 -> #REF!
B24: Фреш 100 | C24: 0.2 | D24: 250 | E24: =D24*C24 -> 50
B25: Сок ананас 300 | C25: 0.3 | D25: =#REF! -> #REF! | E25: =D25*C25 -> #REF!
B26: Сироп кокос 100 | C26: 0.1 | D26: 420 | E26: =D26*C26 -> 42
E27: =D27*C27 -> 0
A28: Биг Голубая Лагуна | B28: Хаски 200 | C28: 0.2 | D28: =#REF! -> #REF! | E28: =D28*C28 -> #REF! | F28: =SUM(E28:E33) -> #REF! | G28: 2000 | H28: =(G28-F28)/F28*100 -> #REF!
B29: Ликер блю Кюрасао 100 | C29: 0.1 | D29: =#REF! -> #REF! | E29: =D29*C29 -> #REF!
B30: Фреш 100 | C30: 0.2 | D30: 250 | E30: =D30*C30 -> 50
B31: Севен ап 350 | C31: 0.35 | D31: =#REF! -> #REF! | E31: =D31*C31 -> #REF!
E32: =D32*C32 -> 0
E33: =D33*C33 -> 0
A34: Биг Берри Маргарита | B34: Текила Хаус 250 | C34: 0.25 | D34: =#REF! -> #REF! | E34: =D34*C34 -> #REF! | F34: =SUM(E34:E39) -> #REF! | G34: 2000 | H34: =(G34-F34)/F34*100 -> #REF!
B35: Ликер малина 125 | C35: 0.125 | D35: =#REF! -> #REF! | E35: =D35*C35 -> #REF!
B36: Фреш 200 | C36: 0.4 | D36: 250 | E36: =D36*C36 -> 100
B37: Сироп гренадин 125 | C37: 0.125 | D37: 420 | E37: =D37*C37 -> 52.5
B38: Пиво корона 1б | C38: 1 | D38: 150 | E38: 150
E39: =D39/1000*C39 -> 0

Sheet майские
A1: Наименование | B1: Состав | C1: объем | D1: ст. литра | E1: сс | F1: сс позиции | G1: Цена | H1: НАЦЕНКА
A2: Darkness 300ml | B2: Ром 40 | C2: 0.04 | D2: =#REF! -> #REF! | E2: =D2*C2 -> #REF! | F2: =SUM(E2:E7) -> #REF! | G2: 750 | H2: =(G2-F2)/F2*100 -> #REF!
B3: Самбука 20 | C3: 0.02 | D3: =#REF! -> #REF! | E3: =D3*C3 -> #REF!
B4: Блю курасао 20 | C4: 0.02 | D4: =#REF! -> #REF! | E4: =D4*C4 -> #REF!
B5: Сироп гренадин 15 | C5: 0.015 | D5: 480 | E5: =D5*C5 -> 7.2
B6: Лимон фреш 15 | C6: 0.03 | D6: 260 | E6: =D6*C6 -> 7.8
B7: Сок грейпфрут 60 | C7: 0.06 | D7: 170 | E7: =D7*C7 -> 10.2
A8: GTFO | B8: Водка20 | C8: 0.02 | D8: =#REF! -> #REF! | E8: =D8*C8 -> #REF! | F8: =SUM(E8:E15) -> #REF! | G8: 750 | H8: =(G8-F8)/F8*100 -> #REF!
B9: джин 20 | C9: 0.02 | D9: =#REF! -> #REF! | E9: =D9*C9 -> #REF!
B10: ром 20 | C10: 0.02 | D10: =#REF! -> #REF! | E10: =D10*C10 -> #REF!
B11: текила20 | C11: 0.02 | D11: =#REF! -> #REF! | E11: =D11*C11 -> #REF!
B12: блю кюрасао20 | C12: 0.02 | D12: =#REF! -> #REF! | E12: =D12*C12 -> #REF!
B13: Сироп кокос 5 | C13: 0.005 | D13: 480 | E13: =D13*C13 -> 2.4
B14: Лимон фреш 10 | C14: 0.02 | D14: 260 | E14: =D14*C14 -> 5.2
B15: Спрайт 50 | C15: 0.05 | D15: =#REF! -> #REF! | E15: =D15*C15 -> #REF!
A16: LipStick | B16: Водка - 40 | C16: 0.04 | D16: =#REF! -> #REF! | E16: =D16*C16 -> #REF! | F16: =SUM(E16:E22) -> #REF! | G16: 750 | H16: =(G16-F16)/F16*100 -> #REF!
B17: Фреш - 20 | C17: 0.02 | D17: 260 | E17: =D17*C17 -> 5.2
B18: Сироп миндаль - 20 | C18: 0.02 | D18: 480 | E18: =D18*C18 -> 9.6
B19: Сироп вишня - 20 | C19: 0.02 | D19: 480 | E19: =D19*C19 -> 9.6
B20: Спрайт - 80 | C20: 0.08 | D20: =#REF! -> #REF! | E20: =D20*C20 -> #REF!
E21: =D21*C21 -> 0
E22: =D22*C22 -> 0
A23: HYPNOTize | B23: Ром 40 | C23: 0.04 | D23: =#REF! -> #REF! | E23: =D23*C23 -> #REF! | F23: =SUM(E23:E28) -> #REF! | G23: 750 | H23: =(G23-F23)/F23*100 -> #REF!
B24: Ликер Нива личи 20 | C24: 0.02 | D24: =#REF! -> #REF! | E24: =D24*C24 -> #REF!
B25: Лимонный 20 | C25: 0.04 | D25: 260 | E25: =D25*C25 -> 10.4
B26: Пюре марайя 20 | C26: 0.02 | D26: =#REF! -> #REF! | E26: =D26*C26 -> #REF!
B27: Сок грейпфрут 40 | C27: 0.04 | D27: 170 | E27: =D27*C27 -> 6.8
B28: Сок ананас 20 | C28: 0.02 | D28: 170 | E28: =D28*C28 -> 3.4
A29: Guilty vanilla | B29: Джин хаус 40 | C29: 0.04 | D29: =#REF! -> #REF! | E29: =D29*C29 -> #REF! | F29: =SUM(E29:E34) -> #REF! | G29: 750 | H29: =(G29-F29)/F29*100 -> #REF!
B30: лимонный сок 30 | C30: 0.06 | D30: 260 | E30: =D30*C30 -> 15.6
B31: Ваниль сироп 20 | C31: 0.02 | D31: 480 | E31: =D31*C31 -> 9.6
B32: Кордиал бобы тонка 30 | C32: 0.03 | D32: =#REF! -> #REF! | E32: =D32*C32 -> #REF!
B33: Яблоко сок 60 | C33: 0.06 | D33: 170 | E33: =D33*C33 -> 10.2
E34: =D34*C34 -> 0
A35: Tropics | B35: 40 ром хаус | C35: 0.04 | D35: =#REF! -> #REF! | E35: =D35*C35 -> #REF! | F35: =SUM(E35:E40) -> #REF! | G35: 750 | H35: =(G35-F35)/F35*100 -> #REF!
B36: 20 трип сек | C36: 0.02 | D36: =#REF! -> #REF! | E36: =D36*C36 -> #REF!
B37: 20 сироп кокос | C37: 0.02 | D37: 480 | E37: =D37*C37 -> 9.6
B38: 60 сок ананас | C38: 0.06 | D38: 170 | E38: =D38*C38 -> 10.2
B39: 10 лимонка | C39: 0.02 | D39: 260 | E39: =D39*C39 -> 5.2
E40: =D40*C40 -> 0
...

Sheet мексика
A1: Наименование | B1: Состав | C1: объем | D1: ст. литра | E1: сс | F1: сс позиции | G1: Цена | H1: НАЦЕНКА
A2: Viva la Mexico, 300ml | B2: Tequila El Charro 0,04 | C2: 0.04 | D2: =#REF! -> #REF! | E2: =D2*C2 -> #REF! | F2: =SUM(E2:E9) -> #REF! | G2: 1000 | H2: =(G2-F2)/F2*100 -> #REF!
B3: Martini bianco 0,02 | C3: 0.02 | D3: =#REF! -> #REF! | E3: =D3*C3 -> #REF!
B4: Syrup grenadine 0,02 | C4: 0.02 | D4: 480 | E4: =D4*C4 -> 9.6
B5: Grapefruit juice 0,05 | C5: 0.05 | D5: 170 | E5: =D5*C5 -> 8.5
B6: Lemon fresh 0,015 | C6: 0.03 | D6: 260 | E6: =D6*C6 -> 7.8
B7: Egg white 0,03 | C7: 0.03 | D7: =#REF! -> #REF! | E7: =D7*C7 -> #REF!
B8: Flowers | E8: 10
E9: =D9*C9 -> 0
A10: Fiesta, 350ml | B10: Tequila El Charro 0,03 | C10: 0.03 | D10: =#REF! -> #REF! | E10: =D10*C10 -> #REF! | F10: =SUM(E10:E17) -> #REF! | G10: 1000 | H10: =(G10-F10)/F10*100 -> #REF!
B11: Niva Distillery Aperitivo 0,03 | C11: 0.03 | D11: =#REF! -> #REF! | E11: =D11*C11 -> #REF!
B12: Clavis cordial yuzu 0,03 | C12: 0.03 | D12: =#REF! -> #REF! | E12: =D12*C12 -> #REF!
B13: Niva Distillery liquor peach 0,02 | C13: 0.02 | D13: =#REF! -> #REF! | E13: =D13*C13 -> #REF!
B14: Lemon fresh 0,015 | C14: 0.03 | D14: 260 | E14: =D14*C14 -> 7.8
B15: Tonic 0,05 | C15: 0.05 | D15: =#REF! -> #REF! | E15: =D15*C15 -> #REF!
B16: Sparkling water 0,05 | C16: 0.05 | D16: =39*2 -> 78 | E16: =D16*C16 -> 3.9
B17: Flowers | E17: 10
A18: Michelada, 350ml | B18: Lemon fresh 0,02 | C18: 0.04 | D18: 260 | E18: =D18*C18 -> 10.4 | F18: =SUM(E18:E26) -> 211.14 | G18: 1100 | H18: =(G18-F18)/F18*100 -> 420.98134
B19: Tomato juice 0,1 | C19: 0.1 | D19: 170 | E19: =D19*C19 -> 17
B20: Worcestershire sauce 0,005 | C20: 0.005 | D20: 994 | E20: =D20*C20 -> 4.97
B21: Tabasco 0,003 | C21: 0.003 | D21: 3700 | E21: =D21*C21 -> 11.1
B22: Salt | C22: 0.001 | D22: 70 | E22: =D22*C22 -> 0.07
B23: Pepper | C23: 0.001 | D23: 5000 | E23: =D23*C23 -> 5
B24: Corona beer 1б | C24: 1 | D24: 150 | E24: =D24*C24 -> 150
B25: Tomato | C25: 0.02 | D25: 500 | E25: =D25*C25 -> 10
B26: Lime 0,01 | C26: 0.01 | D26: 260 | E26: =D26*C26 -> 2.6
A27: Silver Bullet | B27: Tequila El Charro 0,06 | C27: 0.06 | D27: =#REF! -> #REF! | E27: =D27*C27 -> #REF! | F27: =SUM(E27:E34) -> #REF! | G27: 1200 | H27: =(G27-F27)/F27*100 -> #REF!
B28: Lemon fresh 0,04 | C28: 0.08 | D28: 260 | E28: =D28*C28 -> 20.8
B29: Niva Distillery Liquor coffee 0,06 | C29: 0.06 | D29: =#REF! -> #REF! | E29: =D29*C29 -> #REF!
E30: =D30*C30 -> 0
E31: =D31*C31 -> 0
E32: =D32*C32 -> 0
E33: =D33*C33 -> 0
E34: =D34*C34 -> 0

Sheet нулевые
A1: Наименование | B1: Состав | C1: объем | D1: ст. литра | E1: сс | F1: сс позиции | G1: Цена | H1: НАЦЕНКА
A2: Moscow never sleep, 300ml | B2: Tundra 0,04 | C2: 0.04 | D2: =#REF! -> #REF! | E2: =D2*C2 -> #REF! | F2: =SUM(E2:E9) -> #REF! | G2: 700 | H2: =(G2-F2)/F2*100 -> #REF!
B3: Niva Distillery Liquor Elderflower 0,02 | C3: 0.02 | D3: =#REF! -> #REF! | E3: =D3*C3 -> #REF!
B4: Cola 0,15 | C4: 0.15 | D4: =#REF! -> #REF! | E4: =D4*C4 -> #REF!
B5: Lime 0.015 | C5: 0.03 | D5: 270 | E5: =D5*C5 -> 8.1
E6: =D6*C6 -> 0
E7: =D7*C7 -> 0
E8: 10
E9: =D9*C9 -> 0
A10: Pop star, 250ml | B10: Rum Diablo Negro Caribbean 0,04 | C10: 0.04 | D10: =#REF! -> #REF! | E10: =D10*C10 -> #REF! | F10: =SUM(E10:E17) -> #REF! | G10: 750 | H10: =(G10-F10)/F10*100 -> #REF!
B11: Niva Distillery Liquor raspberry 0,02 | C11: 0.02 | D11: =#REF! -> #REF! | E11: =D11*C11 -> #REF!
B12: Niva Distillery Liquor triple sec 0,02 | C12: 0.02 | D12: =#REF! -> #REF! | E12: =D12*C12 -> #REF!
B13: Lemon fresh 0,02 | C13: 0.04 | D13: 270 | E13: =D13*C13 -> 10.8
B14: Syrup cherry 0,02 | C14: 0.02 | D14: 480 | E14: =D14*C14 -> 9.6
B15: Cherry | E15: 10
E16: =D16*C16 -> 0
E17: 10
A18: Мой мармеладный,350ml | B18: Absinthe Oasis 0,015 | C18: 0.015 | D18: =#REF! -> #REF! | E18: =D18*C18 -> #REF! | F18: =SUM(E18:E26) -> #REF! | G18: 750 | H18: =(G18-F18)/F18*100 -> #REF!
B19: Niva Distillery Liqour Blue curaçao 0,015 | C19: 0.015 | D19: =#REF! -> #REF! | E19: =D19*C19 -> #REF!
B20: Niva Distillery Liquor melon 0,03 | C20: 0.03 | D20: =#REF! -> #REF! | E20: =D20*C20 -> #REF!
B21: Syrup coconut 0,015 | C21: 0.015 | D21: 480 | E21: =D21*C21 -> 7.2
B22: Lemon fresh 0,02 | C22: 0.04 | D22: 270 | E22: =D22*C22 -> 10.8
B23: Pineapple juice 0,06 | C23: 0.06 | D23: 170 | E23: =D23*C23 -> 10.2
B24: Orange 0,015 | C24: 0.015 | D24: 270 | E24: =D24*C24 -> 4.05
B25: Cherry | E25: 10
E26: =D26*C26 -> 0
A27: Папарацци | B27: Tequila El Charro 0,04 | C27: 0.04 | D27: =#REF! -> #REF! | E27: =D27*C27 -> #REF! | F27: =SUM(E27:E34) -> #REF! | G27: 1200 | H27: =(G27-F27)/F27*100 -> #REF!
B28: Niva Distillery Liquor melon 0,04 | C28: 0.04 | D28: =#REF! -> #REF! | E28: =D28*C28 -> #REF!
B29: Lemon fresh 0,04 | C29: 0.08 | D29: 270 | E29: =D29*C29 -> 21.6
B30: Syrup banana 0,02 | C30: 0.02 | D30: 480 | E30: =D30*C30 -> 9.6
E31: =D31*C31 -> 0
E32: =D32*C32 -> 0
E33: =D33*C33 -> 0
E34: =D34*C34 -> 0

Sheet ангар спешл
A1: Наименование | B1: Состав | C1: объем | D1: ст. литра | E1: сс | F1: сс позиции | G1: Цена | H1: НАЦЕНКА
A2: Salem, 300ml | B2: Vodka Хаски 0,04 | C2: 0.04 | D2: =#REF! -> #REF! | E2: =D2*C2 -> #REF! | F2: =SUM(E2:E9) -> #REF! | G2: 700 | H2: =(G2-F2)/F2*100 -> #REF!
B3: Niva Distillery Liquor raspberry 0,02 | C3: 0.02 | D3: =#REF! -> #REF! | E3: =D3*C3 -> #REF!
B4: Syrup yuzu 0,02 | C4: 0.02 | D4: =#REF! -> #REF! | E4: =D4*C4 -> #REF!
B5: Apple juice 0,1 | C5: 0.1 | D5: 180 | E5: =D5*C5 -> 18
B6: Lemon fresh 0,02 | C6: 0.04 | D6: 280 | E6: =D6*C6 -> 11.2
B7: Lime 0,01 | C7: 0.01 | D7: 280 | E7: =D7*C7 -> 2.8
E9: =D9*C9 -> 0
A10: 303, 300ml | B10: Rum Diablo Negro Caribbean 0,04 | C10: 0.04 | D10: =#REF! -> #REF! | E10: =D10*C10 -> #REF! | F10: =SUM(E10:E17) -> #REF! | G10: 800 | H10: =(G10-F10)/F10*100 -> #REF!
B11: Niva Distillery Liquor melon 0,02 | C11: 0.02 | D11: =#REF! -> #REF! | E11: =D11*C11 -> #REF!
B12: Passion fruit puree 0,02 | C12: 0.02 | D12: =#REF! -> #REF! | E12: =D12*C12 -> #REF!
B13: Pineapple juice 0,1 | C13: 0.1 | D13: 180 | E13: =D13*C13 -> 18
B14: Lemon fresh 0,02 | C14: 0.04 | D14: 280 | E14: =D14*C14 -> 11.2
B15: Orange 0,015 | C15: 0.015 | D15: 280 | E15: =D15*C15 -> 4.2
E16: =D16*C16 -> 0
E17: =D17*C17 -> 0
A18: Pandemic, 300ml | B18: Sibbitter spice&herb 0,04 | C18: 0.04 | D18: =#REF! -> #REF! | E18: =D18*C18 -> #REF! | F18: =SUM(E18:E26) -> #REF! | G18: 700 | H18: =(G18-F18)/F18*100 -> #REF!
B19: Martini Rosso 0,02 | C19: 0.02 | D19: =#REF! -> #REF! | E19: =D19*C19 -> #REF!
B20: Syrup blackberry 0,02 | C20: 0.02 | D20: =#REF! -> #REF! | E20: =D20*C20 -> #REF!
B21: Grapefruit juice 0,1 | C21: 0.1 | D21: 180 | E21: =D21*C21 -> 18
B22: Lemon fresh 0,02 | C22: 0.04 | D22: 280 | E22: =D22*C22 -> 11.2
B23: Orange 0,015 | C23: 0.015 | D23: 280 | E23: =D23*C23 -> 4.2
E24: =D24*C24 -> 0
E25: =D25*C25 -> 0
E26: =D26*C26 -> 0
A27: Crystal castles, 350ml | B27: Vodka Хаски 0,02 | C27: 0.02 | D27: =#REF! -> #REF! | E27: =D27*C27 -> #REF! | F27: =SUM(E27:E34) -> #REF! | G27: 1000 | H27: =(G27-F27)/F27*100 -> #REF!
B28: Gin Royal Raven Dry 0,02 | C28: 0.02 | D28: =#REF! -> #REF! | E28: =D28*C28 -> #REF!
B29: Rum Diablo Negro Caribbean 0,02 | C29: 0.02 | D29: =#REF! -> #REF! | E29: =D29*C29 -> #REF!
B30: Tequila La mision 0,02 | C30: 0.02 | D30: =#REF! -> #REF! | E30: =D30*C30 -> #REF!
B31: Niva Distillery Liquor melon 0,02 | C31: 0.02 | D31: =#REF! -> #REF! | E31: =D31*C31 -> #REF!
B32: Lemon fresh 0,02 | C32: 0.04 | D32: 280 | E32: =D32*C32 -> 11.2
B33: Seven up 0,1 | C33: 0.1 | D33: =#REF! -> #REF! | E33: =D33*C33 -> #REF!
B34: Lime 0,01 | C34: 0.01 | D34: 280 | E34: =D34*C34 -> 2.8
A35: Dreamcore,300ml | B35: Niva Distillery Liquor triple sec 0,04 | C35: 0.04 | D35: =#REF! -> #REF! | E35: =D35*C35 -> #REF! | F35: =SUM(E35:E42) -> #REF! | G35: 800 | H35: =(G35-F35)/F35*100 -> #REF!
B36: Aperol 0,02 | C36: 0.02 | D36: =#REF! -> #REF! | E36: =D36*C36 -> #REF!
B37: Orange juice 0,05 | C37: 0.05 | D37: 180 | E37: =D37*C37 -> 9
B38: Lemon fresh 0,02 | C38: 0.04 | D38: 280 | E38: =D38*C38 -> 11.2
B39: Syrup grenadine 0,02 | C39: 0.02 | D39: =#REF! -> #REF! | E39: =D39*C39 -> #REF!
B40: Sparkling water 0,05 | C40: 0.1 | D40: =#REF! -> #REF! | E40: =D40*C40 -> #REF!
B41: Orange 0,015 | C41: 0.015 | D41: 280 | E41: =D41*C41 -> 4.2
...

Sheet кунсткамера
A1: Наименование | B1: Состав | C1: объем | D1: ст. литра | E1: сс | F1: сс позиции | G1: Цена | H1: НАЦЕНКА
A2: Малиновая анестезия, 300ml | B2: Gin Royal Raven Dry 0,04 | C2: 0.04 | D2: =#REF! -> #REF! | E2: =D2*C2 -> #REF! | F2: =SUM(E2:E9) -> #REF! | G2: 650 | H2: =(G2-F2)/F2*100 -> #REF!
B3: Syrup raspberry 0,03 | C3: 0.03 | D3: =#REF! -> #REF! | E3: =D3*C3 -> #REF!
B4: Lemon fresh 0,02 | C4: 0.04 | D4: =#REF! -> #REF! | E4: =D4*C4 -> #REF!
B5: Tonic 0,15 | C5: 0.15 | D5: =#REF! -> #REF! | E5: =D5*C5 -> #REF!
B6: Candy | E6: 10
E7: =D7*C7 -> 0
E9: =D9*C9 -> 0
A10: Аномалия вкуса , 300ml | B10: Gin Royal Raven Dry 0,04 | C10: 0.04 | D10: =#REF! -> #REF! | E10: =D10*C10 -> #REF! | F10: =SUM(E10:E17) -> #REF! | G10: 650 | H10: =(G10-F10)/F10*100 -> #REF!
B11: Grapefruit juice 0,08 | C11: 0.08 | D11: =#REF! -> #REF! | E11: =D11*C11 -> #REF!
B12: Lemon fresh 0,03 | C12: 0.06 | D12: =#REF! -> #REF! | E12: =D12*C12 -> #REF!
B13: Syrup cherry 0,03 | C13: 0.03 | D13: =#REF! -> #REF! | E13: =D13*C13 -> #REF!
B14: Tonic 0,05 | C14: 0.05 | D14: =#REF! -> #REF! | E14: =D14*C14 -> #REF!
B15: Candy | E15: 10
E16: =D16*C16 -> 0
E17: =D17*C17 -> 0
A18: Гематома | B18: Niva Distillery Sambuca 0,06 | C18: 0.06 | D18: =#REF! -> #REF! | E18: =D18*C18 -> #REF! | F18: =SUM(E18:E26) -> #REF! | G18: 1400 | H18: =(G18-F18)/F18*100 -> #REF!
B19: Tequila El Charro 0,04 | C19: 0.04 | D19: =#REF! -> #REF! | E19: =D19*C19 -> #REF!
B20: Absinthe Oasis 0,04 | C20: 0.04 | D20: =#REF! -> #REF! | E20: =D20*C20 -> #REF!
B21: Niva Distillery Liquor cream 0,012 | C21: 0.012 | D21: =#REF! -> #REF! | E21: =D21*C21 -> #REF!
B22: Niva Distillery Blue curaçao liquor 0,008 | C22: 0.008 | D22: =#REF! -> #REF! | E22: =D22*C22 -> #REF!
E23: =D23*C23 -> 0
E24: =D24*C24 -> 0
E25: =D25*C25 -> 0
E26: =D26*C26 -> 0
A27: Взрыв мозга | B27: Vodka Хаски 0,06 | C27: 0.06 | D27: =#REF! -> #REF! | E27: =D27*C27 -> #REF! | F27: =SUM(E27:E34) -> #REF! | G27: 1200 | H27: =(G27-F27)/F27*100 -> #REF!
B28: Niva Distillery Liquor peach 0,06 | C28: 0.06 | D28: =#REF! -> #REF! | E28: =D28*C28 -> #REF!
B29: Niva Distillery Liquor cream 0,032 | C29: 0.032 | D29: =#REF! -> #REF! | E29: =D29*C29 -> #REF!
B30: Syrup grenadine 0,008 | C30: 0.008 | D30: =#REF! -> #REF! | E30: =D30*C30 -> #REF!
E31: =D31*C31 -> 0
E32: =D32*C32 -> 0
E33: =D33*C33 -> 0
E34: =D34*C34 -> 0
E35: =D35*C35 -> 0 | F35: =SUM(E35:E42) -> 0 | H35: =(G35-F35)/F35*100 -> #DIV/0!
E36: =D36*C36 -> 0
E37: =D37*C37 -> 0
E38: =D38*C38 -> 0
E39: =D39*C39 -> 0
E40: =D40*C40 -> 0
E41: =D41*C41 -> 0
...

Sheet звонок
A1: Наименование | B1: Состав | C1: объем | D1: ст. литра | E1: сс | F1: сс позиции | G1: Цена | H1: НАЦЕНКА
A2: Последняя парта, 300мл | B2: Niva Distillery Liquor cassis 0,03 | C2: 0.03 | D2: =#REF! -> #REF! | E2: =D2*C2 -> #REF! | F2: =SUM(E2:E9) -> #REF! | G2: 800 | H2: =(G2-F2)/F2*100 -> #REF!
B3: Syrup blackberry 0,015 | C3: 0.015 | D3: =#REF! -> #REF! | E3: =D3*C3 -> #REF!
B4: Sparkling wine 0,15 | C4: 0.15 | D4: =#REF! -> #REF! | E4: =D4*C4 -> #REF!
B5: Flowers | E5: 10
E6: =D6*C6 -> 0
E7: =D7*C7 -> 0
E8: =D8*C8 -> 0
E9: =D9*C9 -> 0
A10: Любимчик завуча, 300мл | B10: Vodka Хаски 0,04 | C10: 0.04 | D10: =#REF! -> #REF! | E10: =D10*C10 -> #REF! | F10: =SUM(E10:E17) -> #REF! | G10: 600 | H10: =(G10-F10)/F10*100 -> #REF!
B11: Niva Distillery Bitter 0,02 | C11: 0.02 | D11: =#REF! -> #REF! | E11: =D11*C11 -> #REF!
B12: Orange juice 0,1 | C12: 0.1 | D12: =#REF! -> #REF! | E12: =D12*C12 -> #REF!
B13: Syrup cherry 0,015 | C13: 0.015 | D13: =#REF! -> #REF! | E13: =D13*C13 -> #REF!
B14: Candy | E14: 10
E15: =D15*C15 -> 0
E16: =D16*C16 -> 0
E17: =D17*C17 -> 0
A18: Танец с физруком, 300мл | B18: Gin Royal Raven Dry 0,04 | C18: 0.04 | D18: =#REF! -> #REF! | E18: =D18*C18 -> #REF! | F18: =SUM(E18:E26) -> #REF! | G18: 700 | H18: =(G18-F18)/F18*100 -> #REF!
B19: Niva Distillery Liquor raspberry 0,02 | C19: 0.02 | D19: =#REF! -> #REF! | E19: =D19*C19 -> #REF!
B20: Syrup grenadine 0,01 | C20: 0.01 | D20: =#REF! -> #REF! | E20: =D20*C20 -> #REF!
B21: Apple juice 0,06 | C21: 0.06 | D21: =#REF! -> #REF! | E21: =D21*C21 -> #REF!
B22: Seven up 0,05 | C22: 0.05 | D22: =#REF! -> #REF! | E22: =D22*C22 -> #REF!
B23: Orange | C23: 0.02 | D23: =#REF! -> #REF! | E23: =D23*C23 -> #REF!
E24: =D24*C24 -> 0
E25: =D25*C25 -> 0
E26: =D26*C26 -> 0
A27: А голову ты дома не забыл?! | B27: Sibbitter spice herb 0,04 | C27: 0.04 | D27: =#REF! -> #REF! | E27: =D27*C27 -> #REF! | F27: =SUM(E27:E34) -> #REF! | G27: 1000 | H27: =(G27-F27)/F27*100 -> #REF!
B28: Lemon fresh 0,04 | C28: 0.08 | D28: =#REF! -> #REF! | E28: =D28*C28 -> #REF!
B29: Niva Distillery Liquor elderflower 0,04 | C29: 0.04 | D29: =#REF! -> #REF! | E29: =D29*C29 -> #REF!
B30: Syrup yuzu 0,04 | C30: 0.04 | D30: =#REF! -> #REF! | E30: =D30*C30 -> #REF!
E31: =D31*C31 -> 0
E32: =D32*C32 -> 0
E33: =D33*C33 -> 0
E34: =D34*C34 -> 0
E35: =D35*C35 -> 0 | F35: =SUM(E35:E42) -> 0 | H35: =(G35-F35)/F35*100 -> #DIV/0!
E36: =D36*C36 -> 0
E37: =D37*C37 -> 0
E38: =D38*C38 -> 0
E39: =D39*C39 -> 0
E40: =D40*C40 -> 0
...

Sheet ба
A1: Наименование | B1: Состав | C1: объем | D1: ст. литра | E1: сс | F1: сс позиции | G1: Цена | H1: НАЦЕНКА
A2: Cherry-Almond, 300ml | B2: Syrup cherry 0,02 | C2: 0.02 | D2: =#REF! -> #REF! | E2: =D2*C2 -> #REF! | F2: =SUM(E2:E6) -> #REF! | G2: 300 | H2: =(G2-F2)/F2*100 -> #REF!
B3: Syrup almond 0,01 | C3: 0.01 | D3: =#REF! -> #REF! | E3: =D3*C3 -> #REF!
B4: Lemon fresh 0,02 | C4: 0.04 | D4: =#REF! -> #REF! | E4: =D4*C4 -> #REF!
B5: Seven up 0,12 | C5: 0.12 | D5: =#REF! -> #REF! | E5: =D5*C5 -> #REF!
B6: Lemon 0,01 | C6: 0.01 | D6: =#REF! -> #REF! | E6: =D6*C6 -> #REF!
A7: Banana free, 300ml | B7: Pineapple juice 0,05 | C7: 0.05 | D7: =#REF! -> #REF! | E7: =D7*C7 -> #REF! | F7: =SUM(E7:E12) -> #REF! | G7: 450 | H7: =(G7-F7)/F7*100 -> #REF!
B8: Grapefruit juice 0,05 | C8: 0.05 | D8: =#REF! -> #REF! | E8: =D8*C8 -> #REF!
B9: Syrup banana 0,015 | C9: 0.015 | D9: =#REF! -> #REF! | E9: =D9*C9 -> #REF!
B10: Lemon fresh 0,02 | C10: 0.04 | D10: =#REF! -> #REF! | E10: =D10*C10 -> #REF!
B11: Passion fruit puree 0,02 | C11: 0.02 | D11: =#REF! -> #REF! | E11: =D11*C11 -> #REF!
B12: Orange 0,015 | C12: 0.015 | D12: =#REF! -> #REF! | E12: =D12*C12 -> #REF!
A13: Vanilla-apple, 300ml | B13: Syrup vanilla 0,03 | C13: 0.03 | D13: =#REF! -> #REF! | E13: =D13*C13 -> #REF! | F13: =SUM(E13:E17) -> #REF! | G13: 300 | H13: =(G13-F13)/F13*100 -> #REF!
B14: Lemon fresh 0,02 | C14: 0.04 | D14: =#REF! -> #REF! | E14: =D14*C14 -> #REF!
B15: Apple juice 0,08 | C15: 0.08 | D15: 170 | E15: =D15*C15 -> 13.6
B16: Sparkling water 0,05 | C16: 0.05 | D16: 40 | E16: =D16*C16 -> 2
B17: Lemon 0,01 | C17: 0.01 | D17: 300 | E17: =D17*C17 -> 3
A18: Pina colada, 300ml | B18: Pineapple juice 0,1 | C18: 0.1 | D18: =#REF! -> #REF! | E18: =D18*C18 -> #REF! | F18: =SUM(E18:E21) -> #REF! | G18: 300 | H18: =(G18-F18)/F18*100 -> #REF!
B19: Syrup coconut 0,02 | C19: 0.02 | D19: =#REF! -> #REF! | E19: =D19*C19 -> #REF!
B20: Cream 0,02 | C20: 0.02 | D20: =#REF! -> #REF! | E20: =D20*C20 -> #REF!
B21: Orange 0,015 | C21: 0.015 | D21: 300 | E21: =D21*C21 -> 4.5
A22: Yuzu-grapefruit, 300ml | B22: Grapefruit juice 0,01 | C22: 0.01 | D22: =#REF! -> #REF! | E22: =D22*C22 -> #REF! | F22: =SUM(E22:E26) -> #REF! | G22: 300 | H22: =(G22-F22)/F22*100 -> #REF!
B23: Syrup yuzu 0,02 | C23: 0.02 | D23: =#REF! -> #REF! | E23: =D23*C23 -> #REF!
B24: Lemon fresh 0,015 | C24: 0.03 | D24: =#REF! -> #REF! | E24: =D24*C24 -> #REF!
B25: Tonic 0,05 | C25: 0.05 | D25: =#REF! -> #REF! | E25: =D25*C25 -> #REF!
B26: Lime 0,01 | C26: 0.01 | D26: =#REF! -> #REF! | E26: =D26*C26 -> #REF!
A27: Red passion, 300ml | B27: Pineapple juice 0,08 | C27: 0.08 | D27: =#REF! -> #REF! | E27: =D27*C27 -> #REF! | F27: =SUM(E27:E32) -> #REF! | G27: 450 | H27: =(G27-F27)/F27*100 -> #REF!
B28: Passion fruit puree 0,02 | C28: 0.02 | D28: =#REF! -> #REF! | E28: =D28*C28 -> #REF!
B29: Lemon fresh 0,02 | C29: 0.04 | D29: =#REF! -> #REF! | E29: =D29*C29 -> #REF!
B30: Syrup grenadine 0,02 | C30: 0.02 | D30: =#REF! -> #REF! | E30: =D30*C30 -> #REF!
B31: Seven up 0,05 | C31: 0.05 | D31: =#REF! -> #REF! | E31: =D31*C31 -> #REF!
B32: Orange 0,015 | C32: 0.015 | D32: =#REF! -> #REF! | E32: =D32*C32 -> #REF!
A33: Bubble gum-apple, 300ml | B33: Apple juice 0,1 | C33: 0.1 | D33: =#REF! -> #REF! | E33: =D33*C33 -> #REF! | F33: =SUM(E33:E37) -> #REF! | G33: 300 | H33: =(G33-F33)/F33*100 -> #REF!
B34: Lemon fresh 0,02 | C34: 0.04 | D34: =#REF! -> #REF! | E34: =D34*C34 -> #REF!
B35: Syrup bubble gum 0,015 | C35: 0.015 | D35: =#REF! -> #REF! | E35: =D35*C35 -> #REF!
B36: Seven up 0,08 | C36: 0.08 | D36: =#REF! -> #REF! | E36: =D36*C36 -> #REF!
B37: Lime 0,01 | C37: 0.01 | D37: =#REF! -> #REF! | E37: =D37*C37 -> #REF!
A38: Sunrise free, 300ml | B38: Orange juice 0,1 | C38: 0.1 | D38: =#REF! -> #REF! | E38: =D38*C38 -> #REF! | F38: =SUM(E38:E42) -> #REF! | G38: 300 | H38: =(G38-F38)/F38*100 -> #REF!
B39: Syrup grenadine 0,02 | C39: 0.02 | D39: =#REF! -> #REF! | E39: =D39*C39 -> #REF!
B40: Lemon fresh 0,015 | C40: 0.03 | D40: =#REF! -> #REF! | E40: =D40*C40 -> #REF!
...

Sheet футбольное что-то
A1: Наименование | B1: Состав | C1: объем | D1: ст. литра | E1: сс | F1: сс позиции | G1: Цена | H1: НАЦЕНКА
A2: Selasao | B2: Ром - 40 | C2: 0.04 | D2: =#REF! -> #REF! | E2: =D2*C2 -> #REF! | F2: =SUM(E2:E7) -> #REF! | G2: 650 | H2: =(G2-F2)/F2*100 -> #REF!
B3: Апероль 20 | C3: 0.02 | D3: =#REF! -> #REF! | E3: =D3*C3 -> #REF!
B4: Сироп корицы 20 | C4: 0.02 | D4: =#REF! -> #REF! | E4: =D4*C4 -> #REF!
B5: Сок Грейпа 60 | C5: 0.06 | D5: =#REF! -> #REF! | E5: =D5*C5 -> #REF!
B6: Сок лимона 20 | C6: 0.04 | D6: =#REF! -> #REF! | E6: =D6*C6 -> #REF!
E7: =D7*C7 -> 0
A8: Rio | B8: Виски 40 | C8: 0.04 | D8: =#REF! -> #REF! | E8: =D8*C8 -> #REF! | F8: =SUM(E8:E13) -> #REF! | G8: 650 | H8: =(G8-F8)/F8*100 -> #REF!
B9: Ликер melon 20 | C9: 0.02 | D9: =#REF! -> #REF! | E9: =D9*C9 -> #REF!
B10: Сироп банан 20 | C10: 0.02 | D10: =#REF! -> #REF! | E10: =D10*C10 -> #REF!
B11: Сок лимона 20 | C11: 0.04 | D11: =#REF! -> #REF! | E11: =D11*C11 -> #REF!
B12: Сок яблоко 80 | C12: 0.08 | D12: =#REF! -> #REF! | E12: =D12*C12 -> #REF!
E13: =D13*C13 -> 0
A14: canal oxidado или Saude! | B14: Водка 40 | C14: 0.04 | D14: =#REF! -> #REF! | E14: =D14*C14 -> #REF! | F14: =SUM(E14:E19) -> #REF! | G14: 650 | H14: =(G14-F14)/F14*100 -> #REF!
B15: Ликер кассис 20 | C15: 0.02 | D15: =#REF! -> #REF! | E15: =D15*C15 -> #REF!
B16: Сок лимона 20 | C16: 0.04 | D16: =#REF! -> #REF! | E16: =D16*C16 -> #REF!
B17: Сок апельсин 30 | C17: 0.03 | D17: =#REF! -> #REF! | E17: =D17*C17 -> #REF!
B18: Сироп мед 20 | C18: 0.02 | D18: =#REF! -> #REF! | E18: =D18*C18 -> #REF!
B19: Тоник 20 | C19: 0.02 | D19: =#REF! -> #REF! | E19: =D19*C19 -> #REF!
A20: Salut de familia | B20: Трипло 60 | C20: 0.06 | D20: =#REF! -> #REF! | E20: =D20*C20 -> #REF! | F20: =SUM(E20:E25) -> #REF! | G20: 1200 | H20: =(G20-F20)/F20*100 -> #REF!
B21: Персик 40 | C21: 0.04 | D21: =#REF! -> #REF! | E21: =D21*C21 -> #REF!
B22: Лимон 20 | C22: 0.04 | D22: =#REF! -> #REF! | E22: =D22*C22 -> #REF!
B23: Малиновое пюре 20 | C23: 0.02 | D23: =#REF! -> #REF! | E23: =D23*C23 -> #REF!
E24: =D24*C24 -> 0
E25: =D25*C25 -> 0
A26: Ultima carrera | B26: Самбука-40 | C26: 0.04 | D26: =#REF! -> #REF! | E26: =D26*C26 -> #REF! | F26: =SUM(E26:E31) -> #REF! | G26: 1200 | H26: =(G26-F26)/F26*100 -> #REF!
B27: Кофейный - 80 | C27: 0.08 | D27: =#REF! -> #REF! | E27: =D27*C27 -> #REF!
B28: Сливки-40 | C28: 0.04 | D28: =#REF! -> #REF! | E28: =D28*C28 -> #REF!
E29: =D29*C29 -> 0
E30: =D30*C30 -> 0
E31: =D31*C31 -> 0
E32: =D32*C32 -> 0 | F32: =SUM(E32:E37) -> 0 | H32: =(G32-F32)/F32*100 -> #DIV/0!
E33: =D33*C33 -> 0
E34: =D34*C34 -> 0
E35: =D35*C35 -> 0
E36: =D36*C36 -> 0
E37: =D37*C37 -> 0
E38: =D38*C38 -> 0 | F38: =SUM(E38:E43) -> 0 | H38: =(G38-F38)/F38*100 -> #DIV/0!
E39: =D39*C39 -> 0
E40: =D40*C40 -> 0
...

Sheet офисные
A1: Наименование | B1: Состав | C1: объем | D1: ст. литра | E1: сс | F1: сс позиции | G1: Цена | H1: НАЦЕНКА
A2: Упущенный(пропущенный) дедлайн мисс деад | B2: Джин 40 | C2: 0.04 | D2: =#REF! -> #REF! | E2: =D2*C2 -> #REF! | F2: =SUM(E2:E7) -> #REF! | G2: 650 | H2: =(G2-F2)/F2*100 -> #REF!
B3: Пюре маракуйя 20 | C3: 0.02 | D3: =#REF! -> #REF! | E3: =D3*C3 -> #REF!
B4: Лимонный 20 | C4: 0.04 | D4: =#REF! -> #REF! | E4: =D4*C4 -> #REF!
B5: Малиновый ликер 20 | C5: 0.02 | D5: =#REF! -> #REF! | E5: =D5*C5 -> #REF!
B6: Содовая 80 | C6: 0.08 | D6: =#REF!*2 -> #VALUE! | E6: =D6*C6 -> #VALUE!
E7: =D7*C7 -> 0
A8: Чертова планерка дамн | B8: Водка 40 | C8: 0.04 | D8: =#REF! -> #REF! | E8: =D8*C8 -> #REF! | F8: =SUM(E8:E13) -> #REF! | G8: 650 | H8: =(G8-F8)/F8*100 -> #REF!
B9: Ликер черная смородина 20 | C9: 0.02 | D9: =#REF! -> #REF! | E9: =D9*C9 -> #REF!
B10: Лимонный 20 | C10: 0.04 | D10: =#REF! -> #REF! | E10: =D10*C10 -> #REF!
B11: Сироп черная смородина 10 | C11: 0.01 | D11: =#REF! -> #REF! | E11: =D11*C11 -> #REF!
B12: 7up 80 | C12: 0.08 | D12: =#REF! -> #REF! | E12: =D12*C12 -> #REF!
E13: =D13*C13 -> 0
B14: Водка 40 | C14: 0.04 | D14: =#REF! -> #REF! | E14: =D14*C14 -> #REF! | F14: =SUM(E14:E19) -> #REF! | G14: 650 | H14: =(G14-F14)/F14*100 -> #REF!
B15: Кофейный 20 | C15: 0.02 | D15: =#REF! -> #REF! | E15: =D15*C15 -> #REF!
B16: Кола 120 | C16: 0.04 | D16: =#REF! -> #REF! | E16: =D16*C16 -> #REF!
C17: 0.12 | D17: =#REF! -> #REF! | E17: =D17*C17 -> #REF!
E18: =D18*C18 -> 0
E19: =D19*C19 -> 0
A20: Твое выгорание | B20: Виски 80 | C20: 0.08 | D20: =#REF! -> #REF! | E20: =D20*C20 -> #REF! | F20: =SUM(E20:E25) -> #REF! | G20: 1000 | H20: =(G20-F20)/F20*100 -> #REF!
B21: Сироп Мед 40 | C21: 0.04 | D21: =#REF! -> #REF! | E21: =D21*C21 -> #REF!
B22: Сок яблоко 40 | C22: 0.04 | D22: =#REF! -> #REF! | E22: =D22*C22 -> #REF!
E23: =D23*C23 -> 0
E24: =D24*C24 -> 0
E25: =D25*C25 -> 0
A26: 5 дней Ада сет на 5шотов!!!! | B26: Абсент 80 | C26: 0.08 | D26: =#REF! -> #REF! | E26: =D26*C26 -> #REF! | F26: =SUM(E26:E31) -> #REF! | G26: 1300 | H26: =(G26-F26)/F26*100 -> #REF!
B27: ЛИКЕР Блюха 40 | C27: 0.04 | D27: =#REF! -> #REF! | E27: =D27*C27 -> #REF!
B28: Ваниль сироп 40 | C28: 0.04 | D28: =#REF! -> #REF! | E28: =D28*C28 -> #REF!
B29: Лимон 40 | C29: 0.08 | D29: =#REF! -> #REF! | E29: =D29*C29 -> #REF!
E30: =D30*C30 -> 0
E31: =D31*C31 -> 0
A32: Корпоратив с бухгалтерией корпорат | B32: Джин 80 | C32: 0.08 | D32: =#REF! -> #REF! | E32: =D32*C32 -> #REF! | F32: =SUM(E32:E37) -> #REF! | G32: 1100 | H32: =(G32-F32)/F32*100 -> #REF!
B33: Ликер бузины 40 | C33: 0.04 | D33: =#REF! -> #REF! | E33: =D33*C33 -> #REF!
B34: Лимон 20 | C34: 0.04 | D34: =#REF! -> #REF! | E34: =D34*C34 -> #REF!
B35: Гренадин 20 | C35: 0.02 | D35: =#REF! -> #REF! | E35: =D35*C35 -> #REF!
E36: =D36*C36 -> 0
E37: =D37*C37 -> 0
E38: =D38*C38 -> 0 | F38: =SUM(E38:E43) -> 0 | H38: =(G38-F38)/F38*100 -> #DIV/0!
E39: =D39*C39 -> 0
E40: =D40*C40 -> 0
...

Sheet ганста
A1: Наименование | B1: Состав | C1: объем | D1: ст. литра | E1: сс | F1: сс позиции | G1: Цена | H1: НАЦЕНКА
A2: Impala 63’ | B2: Ром 30 | C2: 0.03 | D2: =#REF! -> #REF! | E2: =D2*C2 -> #REF! | F2: =SUM(E2:E8) -> #REF! | G2: 700 | H2: =(G2-F2)/F2*100 -> #REF!
B3: Сиббитер кола 30 | C3: 0.03 | D3: =#REF! -> #REF! | E3: =D3*C3 -> #REF!
B4: Вермут 20 | C4: 0.02 | D4: =#REF! -> #REF! | E4: =D4*C4 -> #REF!
B5: Лимонный фреш 20 | C5: 0.04 | D5: =#REF! -> #REF! | E5: =D5*C5 -> #REF!
B6: Сироп корица 20 | C6: 0.02 | D6: =#REF! -> #REF! | E6: =D6*C6 -> #REF!
B7: Кола 60 | C7: 0.06 | D7: =#REF! -> #REF! | E7: =D7*C7 -> #REF!
E8: =D8*C8 -> 0
A9: Lin4ik | B9: Джин 60 | C9: 0.06 | D9: =#REF! -> #REF! | E9: =D9*C9 -> #REF! | F9: =SUM(E9:E14) -> #REF! | G9: 700 | H9: =(G9-F9)/F9*100 -> #REF!
B10: Лимонный фреш 30 | C10: 0.06 | D10: =#REF! -> #REF! | E10: =D10*C10 -> #REF!
B11: Сироп Черная смородина 30 | C11: 0.03 | D11: 480 | E11: =D11*C11 -> 14.4
B12: Содовая 60 | C12: 0.06 | D12: =#REF!*2 -> #VALUE! | E12: =D12*C12 -> #VALUE!
B13: Сок апельсин 20 | C13: 0.02 | D13: =#REF! -> #REF! | E13: =D13*C13 -> #REF!
E14: =D14*C14 -> 0
A15: Detroit Soul | B15: Водка 40 | C15: 0.04 | D15: =#REF! -> #REF! | E15: =D15*C15 -> #REF! | F15: =SUM(E15:E20) -> #REF! | G15: 700 | H15: =(G15-F15)/F15*100 -> #REF!
B16: Трипло 20 | C16: 0.02 | D16: =#REF! -> #REF! | E16: =D16*C16 -> #REF!
B17: Сок апельсин 20 | C17: 0.02 | D17: =#REF! -> #REF! | E17: =D17*C17 -> #REF!
B18: Маракуйя пюре 20 | C18: 0.02 | D18: =#REF! -> #REF! | E18: =D18*C18 -> #REF!
B19: Тоник 40 | C19: 0.04 | D19: =#REF! -> #REF! | E19: =D19*C19 -> #REF!
E20: =D20*C20 -> 0
A21: Crips | B21: Трипло 60 | C21: 0.06 | D21: =#REF! -> #REF! | E21: =D21*C21 -> #REF! | F21: =SUM(E21:E26) -> #REF! | G21: 1200 | H21: =(G21-F21)/F21*100 -> #REF!
B22: ликер Блюха 60 | C22: 0.06 | D22: =#REF! -> #REF! | E22: =D22*C22 -> #REF!
B23: Игристое 40 | C23: 0.04 | D23: =#REF! -> #REF! | E23: =D23*C23 -> #REF!
E24: =D24*C24 -> 0
E25: =D25*C25 -> 0
E26: =D26*C26 -> 0
A27: Bloods | B27: Водка 40 | C27: 0.04 | D27: =#REF! -> #REF! | E27: =D27*C27 -> #REF! | F27: =SUM(E27:E32) -> #REF! | G27: 1100 | H27: =(G27-F27)/F27*100 -> #REF!
B28: Лимонный фреш 40 | C28: 0.08 | D28: =#REF! -> #REF! | E28: =D28*C28 -> #REF!
B29: Соджу персик 40 | C29: 0.04 | D29: =#REF! -> #REF! | E29: =D29*C29 -> #REF!
B30: Гренадин 40 | C30: 0.04 | D30: =#REF! -> #REF! | E30: =D30*C30 -> #REF!
E31: =D31*C31 -> 0
E32: =D32*C32 -> 0
E33: =D33*C33 -> 0 | F33: =SUM(E33:E38) -> 0 | H33: =(G33-F33)/F33*100 -> #DIV/0!
E34: =D34*C34 -> 0
E35: =D35*C35 -> 0
E36: =D36*C36 -> 0
E37: =D37*C37 -> 0
E38: =D38*C38 -> 0
E39: =D39*C39 -> 0 | F39: =SUM(E39:E44) -> 0 | H39: =(G39-F39)/F39*100 -> #DIV/0!
E40: =D40*C40 -> 0
...

Sheet жара 25
A1: Наименование | B1: Состав | C1: объем | D1: ст. литра | E1: сс | F1: сс позиции | G1: Цена | H1: НАЦЕНКА
A2: Flowers Spritz | B2: Джин 10 | C2: 0.01 | D2: =#REF! -> #REF! | E2: =D2*C2 -> #REF! | F2: =SUM(E2:E8) -> #REF! | G2: 700 | H2: =(G2-F2)/F2*100 -> #REF!
B3: Ликер Бузины 40 | C3: 0.04 | D3: =#REF! -> #REF! | E3: =D3*C3 -> #REF!
B4: Сироп жасмин 10 | C4: 0.01 | D4: =#REF! -> #REF! | E4: =D4*C4 -> #REF!
B5: Игристое 80 | C5: 0.08 | D5: =#REF! -> #REF! | E5: =D5*C5 -> #REF!
B6: Содовая 20 | C6: 0.02 | D6: =#REF!*2 -> #VALUE! | E6: =D6*C6 -> #VALUE!
E7: =D7*C7 -> 0
E8: =D8*C8 -> 0
A9: Peach Aurora Spritz | B9: Персик ликер 40 | C9: 0.04 | D9: =#REF! -> #REF! | E9: =D9*C9 -> #REF! | F9: =SUM(E9:E14) -> #REF! | G9: 700 | H9: =(G9-F9)/F9*100 -> #REF!
B10: сироп Ваниль 10 | C10: 0.01 | D10: =#REF! -> #REF! | E10: =D10*C10 -> #REF!
B11: Игристое 100 | C11: 0.1 | D11: =#REF! -> #REF! | E11: =D11*C11 -> #REF!
B12: Содовая 20 | C12: 0.02 | D12: =#REF!*2 -> #VALUE! | E12: =D12*C12 -> #VALUE!
E13: =D13*C13 -> 0
E14: =D14*C14 -> 0
A15: Tropicana Spritz | B15: Ликер Кокос 20 | C15: 0.02 | D15: =#REF! -> #REF! | E15: =D15*C15 -> #REF! | F15: =SUM(E15:E20) -> #REF! | G15: 700 | H15: =(G15-F15)/F15*100 -> #REF!
B16: Ликер Дыня 20 | C16: 0.02 | D16: =#REF! -> #REF! | E16: =D16*C16 -> #REF!
B17: Кордиал Пандан Банан 20 | C17: 0.02 | D17: =#REF! -> #REF! | E17: =D17*C17 -> #REF!
B18: Игристое 80 | C18: 0.08 | D18: =#REF! -> #REF! | E18: =D18*C18 -> #REF!
B19: Содовая 20 | C19: 0.02 | D19: =#REF!*2 -> #VALUE! | E19: =D19*C19 -> #VALUE!
E20: =D20*C20 -> 0
A21: Zen Spritz | B21: Ликер Личи 40 | C21: 0.04 | D21: =#REF! -> #REF! | E21: =D21*C21 -> #REF! | F21: =SUM(E21:E26) -> #REF! | G21: 700 | H21: =(G21-F21)/F21*100 -> #REF!
B22: Сироп грейп 20 | C22: 0.02 | D22: =#REF! -> #REF! | E22: =D22*C22 -> #REF!
B23: Сок грейп 30 | C23: 0.03 | D23: =#REF! -> #REF! | E23: =D23*C23 -> #REF!
B24: Игристое 60 | C24: 0.06 | D24: =#REF! -> #REF! | E24: =D24*C24 -> #REF!
B25: Содовая 20 | C25: 0.02 | D25: =#REF!*2 -> #VALUE! | E25: =D25*C25 -> #VALUE!
E26: =D26*C26 -> 0
A27: Aqua Dulce Spritz | B27: Соджу 40 | C27: 0.04 | E27: =D27*C27 -> 0 | F27: =SUM(E27:E32) -> #REF! | G27: 700 | H27: =(G27-F27)/F27*100 -> #REF!
B28: Малина ликер 30 | C28: 0.03 | D28: =#REF! -> #REF! | E28: =D28*C28 -> #REF!
B29: Игристое 80 | C29: 0.08 | D29: =#REF! -> #REF! | E29: =D29*C29 -> #REF!
B30: Содовая 20 | C30: 0.02 | D30: =#REF!*2 -> #VALUE! | E30: =D30*C30 -> #VALUE!
E31: =D31*C31 -> 0
E32: =D32*C32 -> 0
E33: =D33*C33 -> 0 | F33: =SUM(E33:E38) -> 0 | H33: =(G33-F33)/F33*100 -> #DIV/0!
E34: =D34*C34 -> 0
E35: =D35*C35 -> 0
E36: =D36*C36 -> 0
E37: =D37*C37 -> 0
E38: =D38*C38 -> 0
E39: =D39*C39 -> 0 | F39: =SUM(E39:E44) -> 0 | H39: =(G39-F39)/F39*100 -> #DIV/0!
E40: =D40*C40 -> 0
...

Sheet пират
A1: Наименование | B1: Состав | C1: объем | D1: ст. литра | E1: сс | F1: сс позиции | G1: Цена | H1: НАЦЕНКА
A2: Бунт на корабле (300мл | B2: Ром 40 | C2: 0.04 | D2: =#REF! -> #REF! | E2: =D2*C2 -> #REF! | F2: =SUM(E2:E8) -> #REF! | G2: 700 | H2: =(G2-F2)/F2*100 -> #REF!
B3: 2. Сироп Blacberry 20 | C3: 0.02 | D3: =#REF! -> #REF! | E3: =D3*C3 -> #REF!
B4: 3. Лимон сок 20 | C4: 0.02 | D4: =#REF! -> #REF! | E4: =D4*C4 -> #REF!
B5: 4. Апельсиновый сок 30 | C5: 0.03 | D5: =#REF! -> #REF! | E5: =D5*C5 -> #REF!
B6: 5. Игристое 40 | C6: 0.04 | D6: =#REF! -> #REF! | E6: =D6*C6 -> #REF!
E7: =D7*C7 -> 0
E8: =D8*C8 -> 0
A9: Проклятие Дэйви Джонса (300мл) | B9: 1. Ром 40 | C9: 0.04 | D9: =#REF! -> #REF! | E9: =D9*C9 -> #REF! | F9: =SUM(E9:E14) -> #REF! | G9: 700 | H9: =(G9-F9)/F9*100 -> #REF!
B10: 2. Лимон сок 20 | C10: 0.02 | D10: =#REF! -> #REF! | E10: =D10*C10 -> #REF!
B11: 3. Блюха 30 ликер | C11: 0.03 | D11: =#REF! -> #REF! | E11: =D11*C11 -> #REF!
B12: 4. Белок 30 | C12: 0.03 | D12: =#REF! -> #REF! | E12: =D12*C12 -> #REF!
B13: 5. Сироп кокос 20 | C13: 0.02 | D13: =#REF! -> #REF! | E13: =D13*C13 -> #REF!
E14: =D14*C14 -> 0
A15: Сундук Мертвеца (300мл) | B15: Ром - 40 | C15: 0.04 | D15: =#REF! -> #REF! | E15: =D15*C15 -> #REF! | F15: =SUM(E15:E20) -> #REF! | G15: 700 | H15: =(G15-F15)/F15*100 -> #REF!
B16: 2. Лимон сок - 20 | C16: 0.02 | D16: =#REF! -> #REF! | E16: =D16*C16 -> #REF!
B17: 3. Трипло 20 | C17: 0.02 | D17: =#REF! -> #REF! | E17: =D17*C17 -> #REF!
B18: 4. Белок 30 | C18: 0.03 | D18: =#REF! -> #REF! | E18: =D18*C18 -> #REF!
B19: 5. Сироп миндаль 20 | C19: 0.02 | D19: =#REF! -> #REF! | E19: =D19*C19 -> #REF!
E20: =D20*C20 -> 0
A21: Жемчужина Карибов (4х40) | B21: Ром 80 | C21: 0.08 | D21: =#REF! -> #REF! | E21: =D21*C21 -> #REF! | F21: =SUM(E21:E26) -> #REF! | G21: 1200 | H21: =(G21-F21)/F21*100 -> #REF!
B22: 2. Клавис груша жасмин виноград 30 | C22: 0.03 | D22: =#REF! -> #REF! | E22: =D22*C22 -> #REF!
B23: 3. Лимонный сок 20 | C23: 0.02 | D23: =#REF! -> #REF! | E23: =D23*C23 -> #REF!
B24: 4. Бабл гам сироп 30 | C24: 0.03 | D24: =#REF! -> #REF! | E24: =D24*C24 -> #REF!
E25: =D25*C25 -> 0
E26: =D26*C26 -> 0
A27: Бухта Скелетов (4х40 | B27: 1. Ром 50 | C27: 0.05 | D27: =#REF! -> #REF! | E27: =D27*C27 -> #REF! | F27: =SUM(E27:E32) -> #REF! | G27: 1200 | H27: =(G27-F27)/F27*100 -> #REF!
B28: 2. Клавис банан 30 | C28: 0.03 | D28: =#REF! -> #REF! | E28: =D28*C28 -> #REF!
B29: 3. Яблоко сок 20 | C29: 0.02 | D29: =#REF! -> #REF! | E29: =D29*C29 -> #REF!
B30: 4. Лимонный сок 20 | C30: 0.02 | D30: =#REF! -> #REF! | E30: =D30*C30 -> #REF!
B31: 5. Ликер персик 40 | C31: 0.04 | D31: =#REF! -> #REF! | E31: =D31*C31 -> #REF!
E32: =D32*C32 -> 0
E33: =D33*C33 -> 0 | F33: =SUM(E33:E38) -> 0 | H33: =(G33-F33)/F33*100 -> #DIV/0!
E34: =D34*C34 -> 0
E35: =D35*C35 -> 0
E36: =D36*C36 -> 0
E37: =D37*C37 -> 0
E38: =D38*C38 -> 0
E39: =D39*C39 -> 0 | F39: =SUM(E39:E44) -> 0 | H39: =(G39-F39)/F39*100 -> #DIV/0!
E40: =D40*C40 -> 0
...

Sheet 90е
A1: Наименование | B1: Состав | C1: объем | D1: ст. литра | E1: сс | F1: сс позиции | G1: Цена | H1: НАЦЕНКА
A2: Blazer 300мл | B2: Джин 40 | C2: 0.04 | D2: =#REF! -> #REF! | E2: =D2*C2 -> #REF! | F2: =SUM(E2:E8) -> #REF! | G2: 650 | H2: =(G2-F2)/F2*100 -> #REF!
B3: Блю Кюрасао ликер 20 | C3: 0.02 | D3: =#REF! -> #REF! | E3: =D3*C3 -> #REF!
B4: Лимонный сок 20 | C4: 0.02 | D4: =#REF! -> #REF! | E4: =D4*C4 -> #REF!
B5: Белок 20 | C5: 0.02 | D5: =#REF! -> #REF! | E5: =D5*C5 -> #REF!
B6: Тоник 80 | C6: 0.08 | D6: =#REF! -> #REF! | E6: =D6*C6 -> #REF!
E7: =D7*C7 -> 0
E8: =D8*C8 -> 0
A9: Jaguar 300мл | B9: Ром 40 | C9: 0.04 | D9: =#REF! -> #REF! | E9: =D9*C9 -> #REF! | F9: =SUM(E9:E14) -> #REF! | G9: 600 | H9: =(G9-F9)/F9*100 -> #REF!
B10: Пюре маракуйя 20 | C10: 0.02 | D10: =#REF! -> #REF! | E10: =D10*C10 -> #REF!
B11: Ананасовый сок 40 | C11: 0.04 | D11: =#REF! -> #REF! | E11: =D11*C11 -> #REF!
B12: Лимонный сок 20 | C12: 0.02 | D12: =#REF! -> #REF! | E12: =D12*C12 -> #REF!
B13: Тоник 60 | C13: 0.06 | D13: =#REF! -> #REF! | E13: =D13*C13 -> #REF!
E14: =D14*C14 -> 0
A15: Strike 300 мл | B15: Водка 40 | C15: 0.04 | D15: =#REF! -> #REF! | E15: =D15*C15 -> #REF! | F15: =SUM(E15:E20) -> #REF! | G15: 700 | H15: =(G15-F15)/F15*100 -> #REF!
B16: Лимонный 20 | C16: 0.02 | D16: =#REF! -> #REF! | E16: =D16*C16 -> #REF!
B17: Ликер малины 20 | C17: 0.02 | D17: =#REF! -> #REF! | E17: =D17*C17 -> #REF!
B18: Сок вишня 30 | C18: 0.03 | D18: =#REF! -> #REF! | E18: =D18*C18 -> #REF!
B19: Рб 1/2 | C19: 0.5 | D19: =#REF! -> #REF! | E19: =D19*C19 -> #REF!
E20: =D20*C20 -> 0
A21: Три топора 4х40 | B21: Вермут Россо 60 | C21: 0.06 | D21: =#REF! -> #REF! | E21: =D21*C21 -> #REF! | F21: =SUM(E21:E26) -> #REF! | G21: 1100 | H21: =(G21-F21)/F21*100 -> #REF!
B22: Трипло 60 | C22: 0.06 | D22: =#REF! -> #REF! | E22: =D22*C22 -> #REF!
B23: Черри сироп 40 | C23: 0.04 | D23: =#REF! -> #REF! | E23: =D23*C23 -> #REF!
E24: =D24*C24 -> 0
E25: =D25*C25 -> 0
E26: =D26*C26 -> 0
A27: MTV Vibes 4х40 | B27: Виски 60 | C27: 0.06 | D27: =#REF! -> #REF! | E27: =D27*C27 -> #REF! | F27: =SUM(E27:E32) -> #REF! | G27: 1000 | H27: =(G27-F27)/F27*100 -> #REF!
B28: Трипло 40 | C28: 0.04 | D28: =#REF! -> #REF! | E28: =D28*C28 -> #REF!
B29: Ванильный сироп 30 | C29: 0.03 | D29: =#REF! -> #REF! | E29: =D29*C29 -> #REF!
B30: Лимонный сок 20 | C30: 0.02 | D30: =#REF! -> #REF! | E30: =D30*C30 -> #REF!
E31: =D31*C31 -> 0
E32: =D32*C32 -> 0
E33: =D33*C33 -> 0 | F33: =SUM(E33:E38) -> 0 | H33: =(G33-F33)/F33*100 -> #DIV/0!
E34: =D34*C34 -> 0
E35: =D35*C35 -> 0
E36: =D36*C36 -> 0
E37: =D37*C37 -> 0
E38: =D38*C38 -> 0
E39: =D39*C39 -> 0 | F39: =SUM(E39:E44) -> 0 | H39: =(G39-F39)/F39*100 -> #DIV/0!
E40: =D40*C40 -> 0
...

Sheet др кх
A1: Наименование | B1: Состав | C1: объем | D1: ст. литра | E1: сс | F1: сс позиции | G1: Цена | H1: НАЦЕНКА
A2: Midnight Coffee | B2: Сиббитер Кола 40 | C2: 0.04 | D2: =#REF! -> #REF! | E2: =D2*C2 -> #REF! | F2: =SUM(E2:E8) -> #REF! | G2: 650 | H2: =(G2-F2)/F2*100 -> #REF!
B3: Кофейный ликер 20 | C3: 0.02 | D3: =#REF! -> #REF! | E3: =D3*C3 -> #REF!
B4: Ванильный сироп 20 | C4: 0.02 | D4: =#REF! -> #REF! | E4: =D4*C4 -> #REF!
B5: Белок 20 | C5: 0.02 | D5: =#REF! -> #REF! | E5: =D5*C5 -> #REF!
E6: =D6*C6 -> 0
E7: =D7*C7 -> 0
E8: =D8*C8 -> 0
A9: Milkshake Collin’s (Milk + by VNVNC) | B9: Водка 40 | C9: 0.04 | D9: =#REF! -> #REF! | E9: =D9*C9 -> #REF! | F9: =SUM(E9:E14) -> #REF! | G9: 650 | H9: =(G9-F9)/F9*100 -> #REF!
B10: Ликер малины 20 | C10: 0.02 | D10: =#REF! -> #REF! | E10: =D10*C10 -> #REF!
B11: Пюре малины 20 | C11: 0.02 | D11: =#REF! -> #REF! | E11: =D11*C11 -> #REF!
B12: Сливки 40 | C12: 0.04 | D12: =#REF! -> #REF! | E12: =D12*C12 -> #REF!
B13: Содовая 20 | C13: 0.02 | D13: 79 | E13: =D13*C13 -> 1.58
E14: =D14*C14 -> 0
A15: Emerald Glow | B15: Водка 30 | C15: 0.03 | D15: =#REF! -> #REF! | E15: =D15*C15 -> #REF! | F15: =SUM(E15:E20) -> #REF! | G15: 650 | H15: =(G15-F15)/F15*100 -> #REF!
B16: Ликер Мелон 20 | C16: 0.02 | D16: =#REF! -> #REF! | E16: =D16*C16 -> #REF!
B17: Блю Кюрасао 20 | C17: 0.02 | D17: =#REF! -> #REF! | E17: =D17*C17 -> #REF!
B18: Лимон 20 | C18: 0.02 | D18: =#REF! -> #REF! | E18: =D18*C18 -> #REF!
B19: Ананас сок 20 | C19: 0.02 | D19: =#REF! -> #REF! | E19: =D19*C19 -> #REF!
B20: Белок 20 | C20: 0.02 | D20: =#REF! -> #REF! | E20: =D20*C20 -> #REF!
A21: My little Hommie | B21: Ром - 60 | C21: 0.06 | D21: =#REF! -> #REF! | E21: =D21*C21 -> #REF! | F21: =SUM(E21:E26) -> #REF! | G21: 1000 | H21: =(G21-F21)/F21*100 -> #REF!
B22: Сливочный ликер 30 | C22: 0.03 | D22: =#REF! -> #REF! | E22: =D22*C22 -> #REF!
B23: Кофейный ликер 30 | C23: 0.03 | D23: =#REF! -> #REF! | E23: =D23*C23 -> #REF!
B24: Ванильный сироп 40 | C24: 0.04 | D24: =#REF! -> #REF! | E24: =D24*C24 -> #REF!
E25: =D25*C25 -> 0
E26: =D26*C26 -> 0
A27: Triple SiX | B27: Джин - 80 | C27: 0.08 | D27: =#REF! -> #REF! | E27: =D27*C27 -> #REF! | F27: =SUM(E27:E32) -> #REF! | G27: 1200 | H27: =(G27-F27)/F27*100 -> #REF!
B28: Малиновое пюре - 40 | C28: 0.04 | D28: 1100 | E28: =D28*C28 -> 44
B29: Малиновый Ликер 40 | C29: 0.04 | D29: =#REF! -> #REF! | E29: =D29*C29 -> #REF!
B30: Табаско 2-3 капли | C30: 0.001 | D30: 1500 | E30: =D30*C30 -> 1.5
E31: =D31*C31 -> 0
E32: =D32*C32 -> 0
A33: Angels | B33: Джин 50 | C33: 0.05 | D33: =#REF! -> #REF! | E33: =D33*C33 -> #REF! | F33: =SUM(E33:E38) -> #REF! | G33: 1100 | H33: =(G33-F33)/F33*100 -> #REF!
B34: Блю Кюрасао 30 | C34: 0.03 | D34: =#REF! -> #REF! | E34: =D34*C34 -> #REF!
B35: Лимонный сок 40 | C35: 0.04 | D35: =#REF! -> #REF! | E35: =D35*C35 -> #REF!
B36: Пюре малины 40 | C36: 0.04 | D36: =#REF! -> #REF! | E36: =D36*C36 -> #REF!
E37: =D37*C37 -> 0
E38: =D38*C38 -> 0
E39: =D39*C39 -> 0 | F39: =SUM(E39:E44) -> 0 | H39: =(G39-F39)/F39*100 -> #DIV/0!
E40: =D40*C40 -> 0
...

Sheet жара 9.25
A1: Наименование | B1: Состав | C1: объем | D1: ст. литра | E1: сс | F1: сс позиции | G1: Цена | H1: НАЦЕНКА
A2: Melon Perle | B2: Ликер кокос 26 | C2: 0.026 | D2: =#REF! -> #REF! | E2: =D2*C2 -> #REF! | F2: =SUM(E2:E8) -> #REF! | G2: 700 | H2: =(G2-F2)/F2*100 -> #REF!
B3: Ликер дыни 26 | C3: 0.026 | D3: =#REF! -> #REF! | E3: =D3*C3 -> #REF!
B4: Игристое 60 | C4: 0.06 | D4: =#REF! -> #REF! | E4: =D4*C4 -> #REF!
B5: Содовая 20 | C5: 0.02 | D5: 79 | E5: =D5*C5 -> 1.58
E6: =D6*C6 -> 0
E7: =D7*C7 -> 0
E8: =D8*C8 -> 0
A9: Velvet bramble | B9: Джин 50 | C9: 0.05 | D9: =#REF! -> #REF! | E9: =D9*C9 -> #REF! | F9: =SUM(E9:E14) -> #REF! | G9: 600 | H9: =(G9-F9)/F9*100 -> #REF!
B10: Лимонный сок 30 | C10: 0.03 | D10: =#REF! -> #REF! | E10: =D10*C10 -> #REF!
B11: Сироп Блэк Берри 30 | C11: 0.03 | D11: =#REF! -> #REF! | E11: =D11*C11 -> #REF!
B12: Содовая 50 | C12: 0.05 | D12: 79 | E12: =D12*C12 -> 3.95
E13: =D13*C13 -> 0
E14: =D14*C14 -> 0
A15: Summer dram | B15: Виски 40 | C15: 0.04 | D15: =#REF! -> #REF! | E15: =D15*C15 -> #REF! | F15: =SUM(E15:E20) -> #REF! | G15: 650 | H15: =(G15-F15)/F15*100 -> #REF!
B16: Ликер персик 20 | C16: 0.02 | D16: =#REF! -> #REF! | E16: =D16*C16 -> #REF!
B17: Сироп банан 20 | C17: 0.02 | D17: =#REF! -> #REF! | E17: =D17*C17 -> #REF!
B18: Сок лимона 20 | C18: 0.02 | D18: =#REF! -> #REF! | E18: =D18*C18 -> #REF!
B19: Сок яблоко 60 | C19: 0.06 | D19: =#REF! -> #REF! | E19: =D19*C19 -> #REF!
E20: =D20*C20 -> 0
A21: In da game | B21: Ром 60 | C21: 0.06 | D21: =#REF! -> #REF! | E21: =D21*C21 -> #REF! | F21: =SUM(E21:E26) -> #REF! | G21: 900 | H21: =(G21-F21)/F21*100 -> #REF!
B22: Ликер кокос 40 | C22: 0.04 | D22: =#REF! -> #REF! | E22: =D22*C22 -> #REF!
B23: Лимонный фреш 30 | C23: 0.03 | D23: =#REF! -> #REF! | E23: =D23*C23 -> #REF!
B24: Сироп ваниль 30 | C24: 0.03 | D24: =#REF! -> #REF! | E24: =D24*C24 -> #REF!
E25: =D25*C25 -> 0
E26: =D26*C26 -> 0
A27: Gin eldorado | B27: Джин 60 | C27: 0.06 | D27: =#REF! -> #REF! | E27: =D27*C27 -> #REF! | F27: =SUM(E27:E32) -> #REF! | G27: 900 | H27: =(G27-F27)/F27*100 -> #REF!
B28: Ликер бузины 40 | C28: 0.04 | D28: =#REF! -> #REF! | E28: =D28*C28 -> #REF!
B29: Лимонный фреш 30 | C29: 0.03 | D29: =#REF! -> #REF! | E29: =D29*C29 -> #REF!
B30: Сироп Гренадин 30 | C30: 0.03 | D30: =#REF! -> #REF! | E30: =D30*C30 -> #REF!
E31: =D31*C31 -> 0
E32: =D32*C32 -> 0
E33: =D33*C33 -> 0 | F33: =SUM(E33:E38) -> 0 | G33: 1100 | H33: =(G33-F33)/F33*100 -> #DIV/0!
E34: =D34*C34 -> 0
E35: =D35*C35 -> 0
E36: =D36*C36 -> 0
E37: =D37*C37 -> 0
E38: =D38*C38 -> 0
E39: =D39*C39 -> 0 | F39: =SUM(E39:E44) -> 0 | H39: =(G39-F39)/F39*100 -> #DIV/0!
E40: =D40*C40 -> 0
...

Sheet хипрок
A1: Наименование | B1: Состав | C1: объем | D1: ст. литра | E1: сс | F1: сс позиции | G1: Цена | H1: НАЦЕНКА
A2: Street king шейк обьем 300 хоп | B2: Водка 40 | C2: 0.04 | D2: =#REF! -> #REF! | E2: =D2*C2 -> #REF! | F2: =SUM(E2:E8) -> #REF! | G2: 700 | H2: =(G2-F2)/F2*100 -> #REF!
B3: Ликер яблоко 20 | C3: 0.02 | D3: =#REF! -> #REF! | E3: =D3*C3 -> #REF!
B4: Лимонный фреш 20 | C4: 0.04 | D4: =#REF! -> #REF! | E4: =D4*C4 -> #REF!
B5: Сироп лайм 20 | C5: 0.02 | D5: =#REF! -> #REF! | E5: =D5*C5 -> #REF!
B6: Содовая 40 | C6: 0.04 | D6: 80 | E6: =D6*C6 -> 3.2
E7: =D7*C7 -> 0
E8: =D8*C8 -> 0
A9: Flow Rider шейк 300мл хоп | B9: Ром 40 | C9: 0.04 | D9: =#REF! -> #REF! | E9: =D9*C9 -> #REF! | F9: =SUM(E9:E14) -> #REF! | G9: 600 | H9: =(G9-F9)/F9*100 -> #REF!
B10: Ликер кокос 20 | C10: 0.02 | D10: =#REF! -> #REF! | E10: =D10*C10 -> #REF!
B11: Пюре маракуйя 20 | C11: 0.02 | D11: =#REF! -> #REF! | E11: =D11*C11 -> #REF!
B12: Белок 20 | C12: 0.02 | D12: =#REF! -> #REF! | E12: =D12*C12 -> #REF!
B13: Лимон 20 | C13: 0.02 | D13: =#REF! -> #REF! | E13: =D13*C13 -> #REF!
E14: =D14*C14 -> 0
